<?xml version="1.0" ?>
<robot name="darm_ros2" xmlns:xacro="http://www.ros.org/wiki/xacro">

    <xacro:include filename="$(find darm_ros2)/description/materials.xacro" />
    <xacro:include filename="$(find darm_ros2)/description/darm.trans" />
    <xacro:include filename="$(find darm_ros2)/description/ros2_control.xacro" />

    <!-- PLUGINS -->
    <gazebo>
        <plugin name="gz::sim::systems::JointStatePublisher" filename="gz-sim-joint-state-publisher-system"/>
    </gazebo>

    <!-- LINKS -->
	<link name="world" />

    <link name="base_link">
        <inertial>
            <origin xyz="-2.48214977716486E-09 1.31657070874586E-10 0.029744552660135" rpy="0 0 0" />
            <mass value="3.94679994437601" />
            <inertia ixx="0.0431256456187624" ixy="-1.74150231764969E-11" ixz="2.65508777971032E-10" iyy="0.04312564565183" iyz="-3.95324375768137E-12" izz="0.0811349502099203" />
        </inertial>
        <visual>
            <geometry> <mesh filename="package://darm_ros2/meshes/base_link.stl" /> </geometry>
            <material name="orange"/>
        </visual>
        <collision>
            <geometry> <mesh filename="package://darm_ros2/meshes/base_link.stl" /> </geometry>
        </collision>
    </link>

    <link name="link_1">
        <inertial>
            <origin xyz="7.15911315456218E-08 8.68939660755098E-09 0.0584380287888475" rpy="0 0 0" />
            <mass value="0.929574003768527" />
            <inertia ixx="0.00221230913328666" ixy="-3.73024066520023E-09" ixz="2.37690034244167E-09" iyy="0.00555836322466348" iyz="4.27114309369668E-10" izz="0.00504882065680784" />
        </inertial>
        <visual>
            <geometry> <mesh filename="package://darm_ros2/meshes/link_1.stl" /> </geometry>
            <material name="orange"/>
        </visual>
        <collision>
            <geometry> <mesh filename="package://darm_ros2/meshes/link_1.stl" /> </geometry>
        </collision>
    </link>

    <link name="link_2">
        <inertial>
            <origin xyz="9.62400180381701E-09 -1.37086921334664E-10 0.0969701828522983" rpy="0 0 0" />
            <mass value="0.599415288390779" />
            <inertia ixx="0.00279842867682668" ixy="2.84949733351285E-12" ixz="-1.54896682375371E-11" iyy="0.00304765284781319" iyz="-2.7667649011426E-13" izz="0.00114528537253384" />
        </inertial>
        <visual>
            <geometry> <mesh filename="package://darm_ros2/meshes/link_2.stl" /> </geometry>
            <material name="orange"/>
        </visual>
        <collision>
            <geometry> <mesh filename="package://darm_ros2/meshes/link_2.stl" /> </geometry>
        </collision>
    </link>

    <link name="link_3">
        <inertial>
            <origin xyz="0.00267869003124433 5.00018886047696E-08 0.0563682767579012" rpy="0 0 0" />
            <mass value="0.287966931095487" />
            <inertia ixx="0.000711193490596281" ixy="-1.3748826737474E-10" ixz="-1.62165030254086E-06" iyy="0.000599618348634449" iyz="-6.54553165240046E-10" izz="0.000489006809690983" />
        </inertial>
        <visual>
            <geometry> <mesh filename="package://darm_ros2/meshes/link_3.stl" /> </geometry>
            <material name="orange"/>
        </visual>
        <collision>
            <geometry> <mesh filename="package://darm_ros2/meshes/link_3.stl" /> </geometry>
        </collision>
    </link>

    <link name="forearm">
        <inertial>
            <origin xyz="-0.0111196882232257 -1.38520825281059E-09 0.139892220718873" rpy="0 0 0" />
            <mass value="0.726179387863323" />
            <inertia ixx="0.00604137800947662" ixy="2.20607343735278E-11" ixz="-0.000870723898953885" iyy="0.00727938326913045" iyz="-6.23876885521001E-11" izz="0.00187146307463222" />
        </inertial>
        <visual>
            <geometry> <mesh filename="package://darm_ros2/meshes/forearm.stl" /> </geometry>
            <material name="orange"/>
        </visual>
        <collision>
            <geometry> <mesh filename="package://darm_ros2/meshes/forearm.stl" /> </geometry>
        </collision>
    </link>

    <link name="differential">
        <inertial>
            <origin xyz="1.02275773739878E-10 1.80304198167004E-10 0.000543571929508047" rpy="0 0 0" />
            <mass value="0.124870511204017" />
            <inertia ixx="3.41480810003697E-05" ixy="-1.54868824146798E-13" ixz="-1.18074691967879E-13" iyy="0.000146971987099205" iyz="-1.24779254989816E-13" izz="0.000144640694046327" />
        </inertial>
        <visual>
            <geometry> <mesh filename="package://darm_ros2/meshes/differential.stl" /> </geometry>
            <material name="orange"/>
        </visual>
        <collision>
            <geometry> <mesh filename="package://darm_ros2/meshes/differential.stl" /> </geometry>
        </collision>
    </link>

    <link name="gripper">
        <inertial>
            <origin xyz="1.47508677544427E-10 -4.19167787497244E-10 0.0486273252910504" rpy="0 0 0" />
            <mass value="0.227833460574031" />
            <inertia ixx="0.000187517505664128" ixy="3.98883278992547E-11" ixz="-3.14443887964494E-12" iyy="0.000227045470734226" iyz="-1.97659223492597E-13" izz="0.000181158961918109" />
        </inertial>
        <visual>
            <geometry> <mesh filename="package://darm_ros2/meshes/gripper.stl" /> </geometry>
            <material name="orange"/>
        </visual>
        <collision>
            <geometry> <mesh filename="package://darm_ros2/meshes/gripper.stl" /> </geometry>
        </collision>
    </link>

    <link name="finger_1">
        <inertial>
            <origin xyz="-0.0397149506377288 0.0043644596805526 0.0174753151362246" rpy="0 0 0" />
            <mass value="0.0333577018228372" />
            <inertia ixx="1.08379131084182E-05" ixy="3.69353084704428E-07" ixz="-1.84217384725127E-07" iyy="1.18448488567153E-05" iyz="7.64596058297597E-07" izz="4.94385971740681E-06" />
        </inertial>
        <visual>
            <geometry> <mesh filename="package://darm_ros2/meshes/finger_1.stl" /> </geometry>
            <material name="rubber"/>
        </visual>
        <collision>
            <geometry> <mesh filename="package://darm_ros2/meshes/finger_1.stl" /> </geometry>
        </collision>
    </link>

    <link name="finger_2">
        <inertial>
            <origin xyz="0.0397149506377779 -0.00436445968013956 0.0174753151362146" rpy="0 0 0" />
            <mass value="0.0333577018228331" />
            <inertia ixx="1.08379131084146E-05" ixy="3.6935308470359E-07" ixz="1.84217384719551E-07" iyy="1.18448488567102E-05" iyz="-7.6459605829553E-07" izz="4.94385971740436E-06" />
        </inertial>
        <visual>
            <geometry> <mesh filename="package://darm_ros2/meshes/finger_2.stl" /> </geometry>
            <material name="rubber"/>
        </visual>
        <collision>
            <geometry> <mesh filename="package://darm_ros2/meshes/finger_2.stl" /> </geometry>
        </collision>
    </link>

    <link name="dock">
        <inertial>
            <origin xyz="-6.06353067490172E-08 0.0224446345139935 -0.212157844299707" rpy="0 0 0" />
            <mass value="0.527745087881467" />
            <inertia ixx="0.000497536173309031" ixy="-6.39662591362518E-10" ixz="1.426171887878E-09" iyy="0.000997647866144999" iyz="2.17268365789033E-05" izz="0.000787144635104907" />
        </inertial>
        <visual>
            <geometry> <mesh filename="package://darm_ros2/meshes/dock.stl" /> </geometry>
            <material name="rubber"/>
        </visual>
        <collision>
            <geometry> <mesh filename="package://darm_ros2/meshes/dock.stl" /> </geometry>
        </collision>
    </link>

    <!-- JOINTS -->
    <joint name="base_joint" type="fixed">
        <origin xyz="0 0 0" rpy="0 0 0"/>
        <parent link="world"/>
        <child link="base_link"/>        
    </joint>

    <joint name="link_1_joint" type="revolute">
        <origin xyz="0 0 0.14444" rpy="0 0 0" />
        <parent link="base_link" />
        <child link="link_1" />
        <axis xyz="0 0 1"/>
        <limit lower="${-pi - 0.5}" upper="${pi + 0.5}" effort="20" velocity="2" />
        <dynamics friction="0.2" />
    </joint>

    <joint name="link_2_joint" type="revolute">
        <origin xyz="0 0 0.07556" rpy="${-113 * pi / 180} 0 0" />
        <parent link="link_1" />
        <child link="link_2" />
        <axis xyz="1 0 0"/>
        <limit lower="-0.001" upper="${226 * pi / 180}" effort="40" velocity="2" />
        <dynamics friction="0.2" />
    </joint>

    <joint name="link_3_joint" type="revolute">
        <origin xyz="0 0 0.18708" rpy="0 0 0" />
        <parent link="link_2" />
        <child link="link_3" />
        <axis xyz="0 0 1" />
        <limit lower="${-pi - 0.5}" upper="${pi + 0.5}" effort="20" velocity="2" />
        <dynamics friction="0.2" />
    </joint>

    <joint name="forearm_joint" type="revolute">
        <origin xyz="0 0 0.06292" rpy="${122.9 * pi / 180} 0 0" />
        <parent link="link_3" />
        <child link="forearm" />
        <axis xyz="-1 0 0"/>
        <limit lower="-0.001" upper="${245.8 * pi / 180}" effort="20" velocity="2" />
        <dynamics friction="0.2" />
    </joint>

    <joint name="differential_joint" type="revolute">
        <origin xyz="0 0 0.34" rpy="0 0 0" />
        <parent link="forearm" />
        <child link="differential" />
        <axis xyz="1 0 0"/>
        <limit lower="${-110 * pi / 180}" upper="${110 * pi / 180}" effort="8" velocity="2" />
        <dynamics friction="0.2" />
    </joint>

    <joint name="gripper_joint" type="revolute">
        <origin xyz="0 0 0.02" rpy="0 0 0" />
        <parent link="differential" />
        <child link="gripper" />
        <axis xyz="0 0 -1" />
        <limit lower="-3.141593" upper="3.141593" effort="8" velocity="2" />
        <dynamics friction="0.2" />
    </joint>

    <joint name="finger_1_joint" type="prismatic">
        <origin xyz="0.05 -0.0035 0.091365" rpy="0 0 0" />
        <parent link="gripper" />
        <child link="finger_1" />
        <axis xyz="1 0 0"/>
        <limit lower="-0.001" upper="0.025" effort="2" velocity="0.5" />
        <dynamics friction="0.1" />
    </joint>

    <joint name="finger_2_joint" type="prismatic">
        <origin xyz="-0.05 0.0035 0.091365" rpy="0 0 0" />
        <parent link="gripper" />
        <child link="finger_2" />
        <axis xyz="-1 0 0"/>
        <limit lower="-0.001" upper="0.025" effort="2" velocity="0.5" />
        <dynamics friction="0.1" />
    </joint>

    <joint name="dock_joint" type="fixed">
		<origin xyz="0 0 0" rpy="1.5707963267949 0 0" />
		<parent link="base_link"/>
		<child link="dock"/>
	</joint>

</robot>